[Step 错误] Episode 1 Step 1: select_actions() takes 8 positional arguments but 9 were given
Traceback (most recent call last):
  File "train.py", line 241, in run_training
    action_indices_a, log_probs_a, value_a, detonate_targets_a, lstm_states_a = agent.select_actions(
TypeError: select_actions() takes 8 positional arguments but 9 were given


[Step 错误] Episode 2 Step 1: select_actions() takes 8 positional arguments but 9 were given
Traceback (most recent call last):
  File "train.py", line 241, in run_training
    action_indices_a, log_probs_a, value_a, detonate_targets_a, lstm_states_a = agent.select_actions(
TypeError: select_actions() takes 8 positional arguments but 9 were given


[Step 错误] Episode 3 Step 1: select_actions() takes 8 positional arguments but 9 were given
Traceback (most recent call last):
  File "train.py", line 241, in run_training
    action_indices_a, log_probs_a, value_a, detonate_targets_a, lstm_states_a = agent.select_actions(
TypeError: select_actions() takes 8 positional arguments but 9 were given


[Step 错误] Episode 4 Step 1: select_actions() takes 8 positional arguments but 9 were given
Traceback (most recent call last):
  File "train.py", line 241, in run_training
    action_indices_a, log_probs_a, value_a, detonate_targets_a, lstm_states_a = agent.select_actions(
TypeError: select_actions() takes 8 positional arguments but 9 were given


[Step 错误] Episode 5 Step 1: select_actions() takes 8 positional arguments but 9 were given
Traceback (most recent call last):
  File "train.py", line 241, in run_training
    action_indices_a, log_probs_a, value_a, detonate_targets_a, lstm_states_a = agent.select_actions(
TypeError: select_actions() takes 8 positional arguments but 9 were given


[Step 错误] Episode 6 Step 1: select_actions() takes 8 positional arguments but 9 were given
Traceback (most recent call last):
  File "train.py", line 241, in run_training
    action_indices_a, log_probs_a, value_a, detonate_targets_a, lstm_states_a = agent.select_actions(
TypeError: select_actions() takes 8 positional arguments but 9 were given


[Step 错误] Episode 7 Step 1: select_actions() takes 8 positional arguments but 9 were given
Traceback (most recent call last):
  File "train.py", line 241, in run_training
    action_indices_a, log_probs_a, value_a, detonate_targets_a, lstm_states_a = agent.select_actions(
TypeError: select_actions() takes 8 positional arguments but 9 were given


[Step 错误] Episode 8 Step 1: select_actions() takes 8 positional arguments but 9 were given
Traceback (most recent call last):
  File "train.py", line 241, in run_training
    action_indices_a, log_probs_a, value_a, detonate_targets_a, lstm_states_a = agent.select_actions(
TypeError: select_actions() takes 8 positional arguments but 9 were given


[Step 错误] Episode 9 Step 1: select_actions() takes 8 positional arguments but 9 were given
Traceback (most recent call last):
  File "train.py", line 241, in run_training
    action_indices_a, log_probs_a, value_a, detonate_targets_a, lstm_states_a = agent.select_actions(
TypeError: select_actions() takes 8 positional arguments but 9 were given


[Step 错误] Episode 10 Step 1: select_actions() takes 8 positional arguments but 9 were given
Traceback (most recent call last):
  File "train.py", line 241, in run_training
    action_indices_a, log_probs_a, value_a, detonate_targets_a, lstm_states_a = agent.select_actions(
TypeError: select_actions() takes 8 positional arguments but 9 were given


[Step 错误] Episode 11 Step 1: select_actions() takes 8 positional arguments but 9 were given
Traceback (most recent call last):
  File "train.py", line 241, in run_training
    action_indices_a, log_probs_a, value_a, detonate_targets_a, lstm_states_a = agent.select_actions(
TypeError: select_actions() takes 8 positional arguments but 9 were given


[Step 错误] Episode 12 Step 1: select_actions() takes 8 positional arguments but 9 were given
Traceback (most recent call last):
  File "train.py", line 241, in run_training
    action_indices_a, log_probs_a, value_a, detonate_targets_a, lstm_states_a = agent.select_actions(
TypeError: select_actions() takes 8 positional arguments but 9 were given


[Step 错误] Episode 13 Step 1: select_actions() takes 8 positional arguments but 9 were given
Traceback (most recent call last):
  File "train.py", line 241, in run_training
    action_indices_a, log_probs_a, value_a, detonate_targets_a, lstm_states_a = agent.select_actions(
TypeError: select_actions() takes 8 positional arguments but 9 were given


[Step 错误] Episode 14 Step 1: select_actions() takes 8 positional arguments but 9 were given
Traceback (most recent call last):
  File "train.py", line 241, in run_training
    action_indices_a, log_probs_a, value_a, detonate_targets_a, lstm_states_a = agent.select_actions(
TypeError: select_actions() takes 8 positional arguments but 9 were given


[Step 错误] Episode 15 Step 1: select_actions() takes 8 positional arguments but 9 were given
Traceback (most recent call last):
  File "train.py", line 241, in run_training
    action_indices_a, log_probs_a, value_a, detonate_targets_a, lstm_states_a = agent.select_actions(
TypeError: select_actions() takes 8 positional arguments but 9 were given


[Step 错误] Episode 1 Step 1: 'PPOModel' object has no attribute 'lstm_hidden_dim'
Traceback (most recent call last):
  File "train.py", line 241, in run_training
    action_indices_a, log_probs_a, value_a, detonate_targets_a, lstm_states_a = agent.select_actions(
  File "/app/agent/ppo_agent.py", line 161, in select_actions
    logits_list, value = self.model(self_states, full_map, lstm_states)
  File "/usr/local/lib/python3.8/site-packages/torch/nn/modules/module.py", line 1518, in _wrapped_call_impl
    return self._call_impl(*args, **kwargs)
  File "/usr/local/lib/python3.8/site-packages/torch/nn/modules/module.py", line 1527, in _call_impl
    return forward_call(*args, **kwargs)
  File "/app/model/ppo_model.py", line 98, in forward
    lstm_out_units = lstm_out.view(B, self.num_units, self.lstm_hidden_dim)  # (B, num_units, lstm_hidden_dim)
  File "/usr/local/lib/python3.8/site-packages/torch/nn/modules/module.py", line 1695, in __getattr__
    raise AttributeError(f"'{type(self).__name__}' object has no attribute '{name}'")
AttributeError: 'PPOModel' object has no attribute 'lstm_hidden_dim'


[Step 错误] Episode 2 Step 1: 'PPOModel' object has no attribute 'lstm_hidden_dim'
Traceback (most recent call last):
  File "train.py", line 241, in run_training
    action_indices_a, log_probs_a, value_a, detonate_targets_a, lstm_states_a = agent.select_actions(
  File "/app/agent/ppo_agent.py", line 161, in select_actions
    logits_list, value = self.model(self_states, full_map, lstm_states)
  File "/usr/local/lib/python3.8/site-packages/torch/nn/modules/module.py", line 1518, in _wrapped_call_impl
    return self._call_impl(*args, **kwargs)
  File "/usr/local/lib/python3.8/site-packages/torch/nn/modules/module.py", line 1527, in _call_impl
    return forward_call(*args, **kwargs)
  File "/app/model/ppo_model.py", line 98, in forward
    lstm_out_units = lstm_out.view(B, self.num_units, self.lstm_hidden_dim)  # (B, num_units, lstm_hidden_dim)
  File "/usr/local/lib/python3.8/site-packages/torch/nn/modules/module.py", line 1695, in __getattr__
    raise AttributeError(f"'{type(self).__name__}' object has no attribute '{name}'")
AttributeError: 'PPOModel' object has no attribute 'lstm_hidden_dim'


[Step 错误] Episode 3 Step 1: 'PPOModel' object has no attribute 'lstm_hidden_dim'
Traceback (most recent call last):
  File "train.py", line 241, in run_training
    action_indices_a, log_probs_a, value_a, detonate_targets_a, lstm_states_a = agent.select_actions(
  File "/app/agent/ppo_agent.py", line 161, in select_actions
    logits_list, value = self.model(self_states, full_map, lstm_states)
  File "/usr/local/lib/python3.8/site-packages/torch/nn/modules/module.py", line 1518, in _wrapped_call_impl
    return self._call_impl(*args, **kwargs)
  File "/usr/local/lib/python3.8/site-packages/torch/nn/modules/module.py", line 1527, in _call_impl
    return forward_call(*args, **kwargs)
  File "/app/model/ppo_model.py", line 98, in forward
    lstm_out_units = lstm_out.view(B, self.num_units, self.lstm_hidden_dim)  # (B, num_units, lstm_hidden_dim)
  File "/usr/local/lib/python3.8/site-packages/torch/nn/modules/module.py", line 1695, in __getattr__
    raise AttributeError(f"'{type(self).__name__}' object has no attribute '{name}'")
AttributeError: 'PPOModel' object has no attribute 'lstm_hidden_dim'


[Step 错误] Episode 4 Step 1: 'PPOModel' object has no attribute 'lstm_hidden_dim'
Traceback (most recent call last):
  File "train.py", line 241, in run_training
    action_indices_a, log_probs_a, value_a, detonate_targets_a, lstm_states_a = agent.select_actions(
  File "/app/agent/ppo_agent.py", line 161, in select_actions
    logits_list, value = self.model(self_states, full_map, lstm_states)
  File "/usr/local/lib/python3.8/site-packages/torch/nn/modules/module.py", line 1518, in _wrapped_call_impl
    return self._call_impl(*args, **kwargs)
  File "/usr/local/lib/python3.8/site-packages/torch/nn/modules/module.py", line 1527, in _call_impl
    return forward_call(*args, **kwargs)
  File "/app/model/ppo_model.py", line 98, in forward
    lstm_out_units = lstm_out.view(B, self.num_units, self.lstm_hidden_dim)  # (B, num_units, lstm_hidden_dim)
  File "/usr/local/lib/python3.8/site-packages/torch/nn/modules/module.py", line 1695, in __getattr__
    raise AttributeError(f"'{type(self).__name__}' object has no attribute '{name}'")
AttributeError: 'PPOModel' object has no attribute 'lstm_hidden_dim'


[Step 错误] Episode 5 Step 1: 'PPOModel' object has no attribute 'lstm_hidden_dim'
Traceback (most recent call last):
  File "train.py", line 241, in run_training
    action_indices_a, log_probs_a, value_a, detonate_targets_a, lstm_states_a = agent.select_actions(
  File "/app/agent/ppo_agent.py", line 161, in select_actions
    logits_list, value = self.model(self_states, full_map, lstm_states)
  File "/usr/local/lib/python3.8/site-packages/torch/nn/modules/module.py", line 1518, in _wrapped_call_impl
    return self._call_impl(*args, **kwargs)
  File "/usr/local/lib/python3.8/site-packages/torch/nn/modules/module.py", line 1527, in _call_impl
    return forward_call(*args, **kwargs)
  File "/app/model/ppo_model.py", line 98, in forward
    lstm_out_units = lstm_out.view(B, self.num_units, self.lstm_hidden_dim)  # (B, num_units, lstm_hidden_dim)
  File "/usr/local/lib/python3.8/site-packages/torch/nn/modules/module.py", line 1695, in __getattr__
    raise AttributeError(f"'{type(self).__name__}' object has no attribute '{name}'")
AttributeError: 'PPOModel' object has no attribute 'lstm_hidden_dim'


[Step 错误] Episode 6 Step 1: 'PPOModel' object has no attribute 'lstm_hidden_dim'
Traceback (most recent call last):
  File "train.py", line 241, in run_training
    action_indices_a, log_probs_a, value_a, detonate_targets_a, lstm_states_a = agent.select_actions(
  File "/app/agent/ppo_agent.py", line 161, in select_actions
    logits_list, value = self.model(self_states, full_map, lstm_states)
  File "/usr/local/lib/python3.8/site-packages/torch/nn/modules/module.py", line 1518, in _wrapped_call_impl
    return self._call_impl(*args, **kwargs)
  File "/usr/local/lib/python3.8/site-packages/torch/nn/modules/module.py", line 1527, in _call_impl
    return forward_call(*args, **kwargs)
  File "/app/model/ppo_model.py", line 98, in forward
    lstm_out_units = lstm_out.view(B, self.num_units, self.lstm_hidden_dim)  # (B, num_units, lstm_hidden_dim)
  File "/usr/local/lib/python3.8/site-packages/torch/nn/modules/module.py", line 1695, in __getattr__
    raise AttributeError(f"'{type(self).__name__}' object has no attribute '{name}'")
AttributeError: 'PPOModel' object has no attribute 'lstm_hidden_dim'


[Step 错误] Episode 7 Step 1: 'PPOModel' object has no attribute 'lstm_hidden_dim'
Traceback (most recent call last):
  File "train.py", line 241, in run_training
    action_indices_a, log_probs_a, value_a, detonate_targets_a, lstm_states_a = agent.select_actions(
  File "/app/agent/ppo_agent.py", line 161, in select_actions
    logits_list, value = self.model(self_states, full_map, lstm_states)
  File "/usr/local/lib/python3.8/site-packages/torch/nn/modules/module.py", line 1518, in _wrapped_call_impl
    return self._call_impl(*args, **kwargs)
  File "/usr/local/lib/python3.8/site-packages/torch/nn/modules/module.py", line 1527, in _call_impl
    return forward_call(*args, **kwargs)
  File "/app/model/ppo_model.py", line 98, in forward
    lstm_out_units = lstm_out.view(B, self.num_units, self.lstm_hidden_dim)  # (B, num_units, lstm_hidden_dim)
  File "/usr/local/lib/python3.8/site-packages/torch/nn/modules/module.py", line 1695, in __getattr__
    raise AttributeError(f"'{type(self).__name__}' object has no attribute '{name}'")
AttributeError: 'PPOModel' object has no attribute 'lstm_hidden_dim'


[Step 错误] Episode 8 Step 1: 'PPOModel' object has no attribute 'lstm_hidden_dim'
Traceback (most recent call last):
  File "train.py", line 241, in run_training
    action_indices_a, log_probs_a, value_a, detonate_targets_a, lstm_states_a = agent.select_actions(
  File "/app/agent/ppo_agent.py", line 161, in select_actions
    logits_list, value = self.model(self_states, full_map, lstm_states)
  File "/usr/local/lib/python3.8/site-packages/torch/nn/modules/module.py", line 1518, in _wrapped_call_impl
    return self._call_impl(*args, **kwargs)
  File "/usr/local/lib/python3.8/site-packages/torch/nn/modules/module.py", line 1527, in _call_impl
    return forward_call(*args, **kwargs)
  File "/app/model/ppo_model.py", line 98, in forward
    lstm_out_units = lstm_out.view(B, self.num_units, self.lstm_hidden_dim)  # (B, num_units, lstm_hidden_dim)
  File "/usr/local/lib/python3.8/site-packages/torch/nn/modules/module.py", line 1695, in __getattr__
    raise AttributeError(f"'{type(self).__name__}' object has no attribute '{name}'")
AttributeError: 'PPOModel' object has no attribute 'lstm_hidden_dim'


[Step 错误] Episode 9 Step 1: 'PPOModel' object has no attribute 'lstm_hidden_dim'
Traceback (most recent call last):
  File "train.py", line 241, in run_training
    action_indices_a, log_probs_a, value_a, detonate_targets_a, lstm_states_a = agent.select_actions(
  File "/app/agent/ppo_agent.py", line 161, in select_actions
    logits_list, value = self.model(self_states, full_map, lstm_states)
  File "/usr/local/lib/python3.8/site-packages/torch/nn/modules/module.py", line 1518, in _wrapped_call_impl
    return self._call_impl(*args, **kwargs)
  File "/usr/local/lib/python3.8/site-packages/torch/nn/modules/module.py", line 1527, in _call_impl
    return forward_call(*args, **kwargs)
  File "/app/model/ppo_model.py", line 98, in forward
    lstm_out_units = lstm_out.view(B, self.num_units, self.lstm_hidden_dim)  # (B, num_units, lstm_hidden_dim)
  File "/usr/local/lib/python3.8/site-packages/torch/nn/modules/module.py", line 1695, in __getattr__
    raise AttributeError(f"'{type(self).__name__}' object has no attribute '{name}'")
AttributeError: 'PPOModel' object has no attribute 'lstm_hidden_dim'


[Step 错误] Episode 10 Step 1: 'PPOModel' object has no attribute 'lstm_hidden_dim'
Traceback (most recent call last):
  File "train.py", line 241, in run_training
    action_indices_a, log_probs_a, value_a, detonate_targets_a, lstm_states_a = agent.select_actions(
  File "/app/agent/ppo_agent.py", line 161, in select_actions
    logits_list, value = self.model(self_states, full_map, lstm_states)
  File "/usr/local/lib/python3.8/site-packages/torch/nn/modules/module.py", line 1518, in _wrapped_call_impl
    return self._call_impl(*args, **kwargs)
  File "/usr/local/lib/python3.8/site-packages/torch/nn/modules/module.py", line 1527, in _call_impl
    return forward_call(*args, **kwargs)
  File "/app/model/ppo_model.py", line 98, in forward
    lstm_out_units = lstm_out.view(B, self.num_units, self.lstm_hidden_dim)  # (B, num_units, lstm_hidden_dim)
  File "/usr/local/lib/python3.8/site-packages/torch/nn/modules/module.py", line 1695, in __getattr__
    raise AttributeError(f"'{type(self).__name__}' object has no attribute '{name}'")
AttributeError: 'PPOModel' object has no attribute 'lstm_hidden_dim'


[Step 错误] Episode 1 Step 1: too many values to unpack (expected 2)
Traceback (most recent call last):
  File "train.py", line 241, in run_training
    action_indices_a, log_probs_a, value_a, detonate_targets_a, lstm_states_a = agent.select_actions(
  File "/app/agent/ppo_agent.py", line 161, in select_actions
    logits_list, value = self.model(self_states, full_map, lstm_states)
ValueError: too many values to unpack (expected 2)


[Step 错误] Episode 2 Step 1: too many values to unpack (expected 2)
Traceback (most recent call last):
  File "train.py", line 241, in run_training
    action_indices_a, log_probs_a, value_a, detonate_targets_a, lstm_states_a = agent.select_actions(
  File "/app/agent/ppo_agent.py", line 161, in select_actions
    logits_list, value = self.model(self_states, full_map, lstm_states)
ValueError: too many values to unpack (expected 2)


[Step 错误] Episode 3 Step 1: too many values to unpack (expected 2)
Traceback (most recent call last):
  File "train.py", line 241, in run_training
    action_indices_a, log_probs_a, value_a, detonate_targets_a, lstm_states_a = agent.select_actions(
  File "/app/agent/ppo_agent.py", line 161, in select_actions
    logits_list, value = self.model(self_states, full_map, lstm_states)
ValueError: too many values to unpack (expected 2)


[Step 错误] Episode 4 Step 1: too many values to unpack (expected 2)
Traceback (most recent call last):
  File "train.py", line 241, in run_training
    action_indices_a, log_probs_a, value_a, detonate_targets_a, lstm_states_a = agent.select_actions(
  File "/app/agent/ppo_agent.py", line 161, in select_actions
    logits_list, value = self.model(self_states, full_map, lstm_states)
ValueError: too many values to unpack (expected 2)


[Step 错误] Episode 5 Step 1: too many values to unpack (expected 2)
Traceback (most recent call last):
  File "train.py", line 241, in run_training
    action_indices_a, log_probs_a, value_a, detonate_targets_a, lstm_states_a = agent.select_actions(
  File "/app/agent/ppo_agent.py", line 161, in select_actions
    logits_list, value = self.model(self_states, full_map, lstm_states)
ValueError: too many values to unpack (expected 2)


[Step 错误] Episode 6 Step 1: too many values to unpack (expected 2)
Traceback (most recent call last):
  File "train.py", line 241, in run_training
    action_indices_a, log_probs_a, value_a, detonate_targets_a, lstm_states_a = agent.select_actions(
  File "/app/agent/ppo_agent.py", line 161, in select_actions
    logits_list, value = self.model(self_states, full_map, lstm_states)
ValueError: too many values to unpack (expected 2)


[Step 错误] Episode 7 Step 1: too many values to unpack (expected 2)
Traceback (most recent call last):
  File "train.py", line 241, in run_training
    action_indices_a, log_probs_a, value_a, detonate_targets_a, lstm_states_a = agent.select_actions(
  File "/app/agent/ppo_agent.py", line 161, in select_actions
    logits_list, value = self.model(self_states, full_map, lstm_states)
ValueError: too many values to unpack (expected 2)


[Step 错误] Episode 8 Step 1: too many values to unpack (expected 2)
Traceback (most recent call last):
  File "train.py", line 241, in run_training
    action_indices_a, log_probs_a, value_a, detonate_targets_a, lstm_states_a = agent.select_actions(
  File "/app/agent/ppo_agent.py", line 161, in select_actions
    logits_list, value = self.model(self_states, full_map, lstm_states)
ValueError: too many values to unpack (expected 2)


[Step 错误] Episode 9 Step 1: too many values to unpack (expected 2)
Traceback (most recent call last):
  File "train.py", line 241, in run_training
    action_indices_a, log_probs_a, value_a, detonate_targets_a, lstm_states_a = agent.select_actions(
  File "/app/agent/ppo_agent.py", line 161, in select_actions
    logits_list, value = self.model(self_states, full_map, lstm_states)
ValueError: too many values to unpack (expected 2)


[Step 错误] Episode 10 Step 1: too many values to unpack (expected 2)
Traceback (most recent call last):
  File "train.py", line 241, in run_training
    action_indices_a, log_probs_a, value_a, detonate_targets_a, lstm_states_a = agent.select_actions(
  File "/app/agent/ppo_agent.py", line 161, in select_actions
    logits_list, value = self.model(self_states, full_map, lstm_states)
ValueError: too many values to unpack (expected 2)


[Step 错误] Episode 11 Step 1: too many values to unpack (expected 2)
Traceback (most recent call last):
  File "train.py", line 241, in run_training
    action_indices_a, log_probs_a, value_a, detonate_targets_a, lstm_states_a = agent.select_actions(
  File "/app/agent/ppo_agent.py", line 161, in select_actions
    logits_list, value = self.model(self_states, full_map, lstm_states)
ValueError: too many values to unpack (expected 2)


[Step 错误] Episode 12 Step 1: too many values to unpack (expected 2)
Traceback (most recent call last):
  File "train.py", line 241, in run_training
    action_indices_a, log_probs_a, value_a, detonate_targets_a, lstm_states_a = agent.select_actions(
  File "/app/agent/ppo_agent.py", line 161, in select_actions
    logits_list, value = self.model(self_states, full_map, lstm_states)
ValueError: too many values to unpack (expected 2)


[Step 错误] Episode 13 Step 1: too many values to unpack (expected 2)
Traceback (most recent call last):
  File "train.py", line 241, in run_training
    action_indices_a, log_probs_a, value_a, detonate_targets_a, lstm_states_a = agent.select_actions(
  File "/app/agent/ppo_agent.py", line 161, in select_actions
    logits_list, value = self.model(self_states, full_map, lstm_states)
ValueError: too many values to unpack (expected 2)


[总体错误] Episode 1 失败: too many values to unpack (expected 2)
Traceback (most recent call last):
  File "train.py", line 308, in run_training
    agent.update_from_buffer(episode_buffer)
  File "/app/agent/ppo_agent.py", line 228, in update_from_buffer
    self.update()
  File "/app/agent/ppo_agent.py", line 264, in update
    logits_list, values = self.model(b_s, b_m)
ValueError: too many values to unpack (expected 2)


[总体错误] Episode 2 失败: too many values to unpack (expected 2)
Traceback (most recent call last):
  File "train.py", line 308, in run_training
    agent.update_from_buffer(episode_buffer)
  File "/app/agent/ppo_agent.py", line 228, in update_from_buffer
    self.update()
  File "/app/agent/ppo_agent.py", line 264, in update
    logits_list, values = self.model(b_s, b_m)
ValueError: too many values to unpack (expected 2)


[总体错误] Episode 3 失败: too many values to unpack (expected 2)
Traceback (most recent call last):
  File "train.py", line 308, in run_training
    agent.update_from_buffer(episode_buffer)
  File "/app/agent/ppo_agent.py", line 228, in update_from_buffer
    self.update()
  File "/app/agent/ppo_agent.py", line 264, in update
    logits_list, values = self.model(b_s, b_m)
ValueError: too many values to unpack (expected 2)


[总体错误] Episode 4 失败: too many values to unpack (expected 2)
Traceback (most recent call last):
  File "train.py", line 308, in run_training
    agent.update_from_buffer(episode_buffer)
  File "/app/agent/ppo_agent.py", line 228, in update_from_buffer
    self.update()
  File "/app/agent/ppo_agent.py", line 264, in update
    logits_list, values = self.model(b_s, b_m)
ValueError: too many values to unpack (expected 2)


[总体错误] Episode 5 失败: too many values to unpack (expected 2)
Traceback (most recent call last):
  File "train.py", line 308, in run_training
    agent.update_from_buffer(episode_buffer)
  File "/app/agent/ppo_agent.py", line 228, in update_from_buffer
    self.update()
  File "/app/agent/ppo_agent.py", line 264, in update
    logits_list, values = self.model(b_s, b_m)
ValueError: too many values to unpack (expected 2)


[总体错误] Episode 6 失败: too many values to unpack (expected 2)
Traceback (most recent call last):
  File "train.py", line 308, in run_training
    agent.update_from_buffer(episode_buffer)
  File "/app/agent/ppo_agent.py", line 228, in update_from_buffer
    self.update()
  File "/app/agent/ppo_agent.py", line 264, in update
    logits_list, values = self.model(b_s, b_m)
ValueError: too many values to unpack (expected 2)


[总体错误] Episode 7 失败: too many values to unpack (expected 2)
Traceback (most recent call last):
  File "train.py", line 308, in run_training
    agent.update_from_buffer(episode_buffer)
  File "/app/agent/ppo_agent.py", line 228, in update_from_buffer
    self.update()
  File "/app/agent/ppo_agent.py", line 264, in update
    logits_list, values = self.model(b_s, b_m)
ValueError: too many values to unpack (expected 2)


[总体错误] Episode 8 失败: too many values to unpack (expected 2)
Traceback (most recent call last):
  File "train.py", line 308, in run_training
    agent.update_from_buffer(episode_buffer)
  File "/app/agent/ppo_agent.py", line 228, in update_from_buffer
    self.update()
  File "/app/agent/ppo_agent.py", line 264, in update
    logits_list, values = self.model(b_s, b_m)
ValueError: too many values to unpack (expected 2)


[总体错误] Episode 9 失败: too many values to unpack (expected 2)
Traceback (most recent call last):
  File "train.py", line 308, in run_training
    agent.update_from_buffer(episode_buffer)
  File "/app/agent/ppo_agent.py", line 228, in update_from_buffer
    self.update()
  File "/app/agent/ppo_agent.py", line 264, in update
    logits_list, values = self.model(b_s, b_m)
ValueError: too many values to unpack (expected 2)


[总体错误] Episode 10 失败: too many values to unpack (expected 2)
Traceback (most recent call last):
  File "train.py", line 308, in run_training
    agent.update_from_buffer(episode_buffer)
  File "/app/agent/ppo_agent.py", line 228, in update_from_buffer
    self.update()
  File "/app/agent/ppo_agent.py", line 264, in update
    logits_list, values = self.model(b_s, b_m)
ValueError: too many values to unpack (expected 2)


[总体错误] Episode 11 失败: too many values to unpack (expected 2)
Traceback (most recent call last):
  File "train.py", line 308, in run_training
    agent.update_from_buffer(episode_buffer)
  File "/app/agent/ppo_agent.py", line 228, in update_from_buffer
    self.update()
  File "/app/agent/ppo_agent.py", line 264, in update
    logits_list, values = self.model(b_s, b_m)
ValueError: too many values to unpack (expected 2)


[总体错误] Episode 12 失败: too many values to unpack (expected 2)
Traceback (most recent call last):
  File "train.py", line 308, in run_training
    agent.update_from_buffer(episode_buffer)
  File "/app/agent/ppo_agent.py", line 228, in update_from_buffer
    self.update()
  File "/app/agent/ppo_agent.py", line 264, in update
    logits_list, values = self.model(b_s, b_m)
ValueError: too many values to unpack (expected 2)


[总体错误] Episode 13 失败: too many values to unpack (expected 2)
Traceback (most recent call last):
  File "train.py", line 308, in run_training
    agent.update_from_buffer(episode_buffer)
  File "/app/agent/ppo_agent.py", line 228, in update_from_buffer
    self.update()
  File "/app/agent/ppo_agent.py", line 264, in update
    logits_list, values = self.model(b_s, b_m)
ValueError: too many values to unpack (expected 2)


[总体错误] Episode 14 失败: too many values to unpack (expected 2)
Traceback (most recent call last):
  File "train.py", line 308, in run_training
    agent.update_from_buffer(episode_buffer)
  File "/app/agent/ppo_agent.py", line 228, in update_from_buffer
    self.update()
  File "/app/agent/ppo_agent.py", line 264, in update
    logits_list, values = self.model(b_s, b_m)
ValueError: too many values to unpack (expected 2)


[总体错误] Episode 15 失败: too many values to unpack (expected 2)
Traceback (most recent call last):
  File "train.py", line 308, in run_training
    agent.update_from_buffer(episode_buffer)
  File "/app/agent/ppo_agent.py", line 228, in update_from_buffer
    self.update()
  File "/app/agent/ppo_agent.py", line 264, in update
    logits_list, values = self.model(b_s, b_m)
ValueError: too many values to unpack (expected 2)


[总体错误] Episode 16 失败: too many values to unpack (expected 2)
Traceback (most recent call last):
  File "train.py", line 308, in run_training
    agent.update_from_buffer(episode_buffer)
  File "/app/agent/ppo_agent.py", line 228, in update_from_buffer
    self.update()
  File "/app/agent/ppo_agent.py", line 264, in update
    logits_list, values = self.model(b_s, b_m)
ValueError: too many values to unpack (expected 2)


[总体错误] Episode 17 失败: too many values to unpack (expected 2)
Traceback (most recent call last):
  File "train.py", line 308, in run_training
    agent.update_from_buffer(episode_buffer)
  File "/app/agent/ppo_agent.py", line 228, in update_from_buffer
    self.update()
  File "/app/agent/ppo_agent.py", line 264, in update
    logits_list, values = self.model(b_s, b_m)
ValueError: too many values to unpack (expected 2)


[总体错误] Episode 18 失败: too many values to unpack (expected 2)
Traceback (most recent call last):
  File "train.py", line 308, in run_training
    agent.update_from_buffer(episode_buffer)
  File "/app/agent/ppo_agent.py", line 228, in update_from_buffer
    self.update()
  File "/app/agent/ppo_agent.py", line 264, in update
    logits_list, values = self.model(b_s, b_m)
ValueError: too many values to unpack (expected 2)


[总体错误] Episode 19 失败: too many values to unpack (expected 2)
Traceback (most recent call last):
  File "train.py", line 308, in run_training
    agent.update_from_buffer(episode_buffer)
  File "/app/agent/ppo_agent.py", line 228, in update_from_buffer
    self.update()
  File "/app/agent/ppo_agent.py", line 264, in update
    logits_list, values = self.model(b_s, b_m)
ValueError: too many values to unpack (expected 2)


[总体错误] Episode 20 失败: too many values to unpack (expected 2)
Traceback (most recent call last):
  File "train.py", line 308, in run_training
    agent.update_from_buffer(episode_buffer)
  File "/app/agent/ppo_agent.py", line 228, in update_from_buffer
    self.update()
  File "/app/agent/ppo_agent.py", line 264, in update
    logits_list, values = self.model(b_s, b_m)
ValueError: too many values to unpack (expected 2)


[总体错误] Episode 21 失败: too many values to unpack (expected 2)
Traceback (most recent call last):
  File "train.py", line 308, in run_training
    agent.update_from_buffer(episode_buffer)
  File "/app/agent/ppo_agent.py", line 228, in update_from_buffer
    self.update()
  File "/app/agent/ppo_agent.py", line 264, in update
    logits_list, values = self.model(b_s, b_m)
ValueError: too many values to unpack (expected 2)


[总体错误] Episode 22 失败: too many values to unpack (expected 2)
Traceback (most recent call last):
  File "train.py", line 308, in run_training
    agent.update_from_buffer(episode_buffer)
  File "/app/agent/ppo_agent.py", line 228, in update_from_buffer
    self.update()
  File "/app/agent/ppo_agent.py", line 264, in update
    logits_list, values = self.model(b_s, b_m)
ValueError: too many values to unpack (expected 2)


[总体错误] Episode 23 失败: too many values to unpack (expected 2)
Traceback (most recent call last):
  File "train.py", line 308, in run_training
    agent.update_from_buffer(episode_buffer)
  File "/app/agent/ppo_agent.py", line 228, in update_from_buffer
    self.update()
  File "/app/agent/ppo_agent.py", line 264, in update
    logits_list, values = self.model(b_s, b_m)
ValueError: too many values to unpack (expected 2)


[总体错误] Episode 24 失败: too many values to unpack (expected 2)
Traceback (most recent call last):
  File "train.py", line 308, in run_training
    agent.update_from_buffer(episode_buffer)
  File "/app/agent/ppo_agent.py", line 228, in update_from_buffer
    self.update()
  File "/app/agent/ppo_agent.py", line 264, in update
    logits_list, values = self.model(b_s, b_m)
ValueError: too many values to unpack (expected 2)


[总体错误] Episode 25 失败: too many values to unpack (expected 2)
Traceback (most recent call last):
  File "train.py", line 308, in run_training
    agent.update_from_buffer(episode_buffer)
  File "/app/agent/ppo_agent.py", line 228, in update_from_buffer
    self.update()
  File "/app/agent/ppo_agent.py", line 264, in update
    logits_list, values = self.model(b_s, b_m)
ValueError: too many values to unpack (expected 2)


[总体错误] Episode 26 失败: too many values to unpack (expected 2)
Traceback (most recent call last):
  File "train.py", line 308, in run_training
    agent.update_from_buffer(episode_buffer)
  File "/app/agent/ppo_agent.py", line 228, in update_from_buffer
    self.update()
  File "/app/agent/ppo_agent.py", line 264, in update
    logits_list, values = self.model(b_s, b_m)
ValueError: too many values to unpack (expected 2)


[总体错误] Episode 27 失败: too many values to unpack (expected 2)
Traceback (most recent call last):
  File "train.py", line 308, in run_training
    agent.update_from_buffer(episode_buffer)
  File "/app/agent/ppo_agent.py", line 228, in update_from_buffer
    self.update()
  File "/app/agent/ppo_agent.py", line 264, in update
    logits_list, values = self.model(b_s, b_m)
ValueError: too many values to unpack (expected 2)


[总体错误] Episode 28 失败: too many values to unpack (expected 2)
Traceback (most recent call last):
  File "train.py", line 308, in run_training
    agent.update_from_buffer(episode_buffer)
  File "/app/agent/ppo_agent.py", line 228, in update_from_buffer
    self.update()
  File "/app/agent/ppo_agent.py", line 264, in update
    logits_list, values = self.model(b_s, b_m)
ValueError: too many values to unpack (expected 2)


[总体错误] Episode 29 失败: too many values to unpack (expected 2)
Traceback (most recent call last):
  File "train.py", line 308, in run_training
    agent.update_from_buffer(episode_buffer)
  File "/app/agent/ppo_agent.py", line 228, in update_from_buffer
    self.update()
  File "/app/agent/ppo_agent.py", line 264, in update
    logits_list, values = self.model(b_s, b_m)
ValueError: too many values to unpack (expected 2)


[总体错误] Episode 30 失败: too many values to unpack (expected 2)
Traceback (most recent call last):
  File "train.py", line 308, in run_training
    agent.update_from_buffer(episode_buffer)
  File "/app/agent/ppo_agent.py", line 228, in update_from_buffer
  File "/app/agent/ppo_agent.py", line 264, in update
    for b_s, b_m, b_a, b_old_lp, b_ret, b_adv in loader:
ValueError: too many values to unpack (expected 2)


[总体错误] Episode 31 失败: too many values to unpack (expected 2)
Traceback (most recent call last):
  File "train.py", line 308, in run_training
    agent.update_from_buffer(episode_buffer)
  File "/app/agent/ppo_agent.py", line 228, in update_from_buffer
  File "/app/agent/ppo_agent.py", line 264, in update
    for b_s, b_m, b_a, b_old_lp, b_ret, b_adv in loader:
ValueError: too many values to unpack (expected 2)


